[2024-11-17T19:43:50.996+0000] {local_task_job_runner.py:123} INFO - ::group::Pre task execution logs
[2024-11-17T19:43:51.003+0000] {taskinstance.py:2613} INFO - Dependencies all met for dep_context=non-requeueable deps ti=<TaskInstance: en_species_etl.load_data_to_s3 manual__2024-11-17T19:43:48.866514+00:00 [queued]>
[2024-11-17T19:43:51.005+0000] {taskinstance.py:2613} INFO - Dependencies all met for dep_context=requeueable deps ti=<TaskInstance: en_species_etl.load_data_to_s3 manual__2024-11-17T19:43:48.866514+00:00 [queued]>
[2024-11-17T19:43:51.005+0000] {taskinstance.py:2866} INFO - Starting attempt 1 of 1
[2024-11-17T19:43:51.010+0000] {taskinstance.py:2889} INFO - Executing <Task(PythonOperator): load_data_to_s3> on 2024-11-17 19:43:48.866514+00:00
[2024-11-17T19:43:51.013+0000] {warnings.py:112} WARNING - /home/***/.local/lib/python3.12/site-packages/***/task/task_runner/standard_task_runner.py:70: DeprecationWarning: This process (pid=447) is multi-threaded, use of fork() may lead to deadlocks in the child.
  pid = os.fork()

[2024-11-17T19:43:51.014+0000] {standard_task_runner.py:72} INFO - Started process 448 to run task
[2024-11-17T19:43:51.014+0000] {standard_task_runner.py:104} INFO - Running: ['***', 'tasks', 'run', 'en_species_etl', 'load_data_to_s3', 'manual__2024-11-17T19:43:48.866514+00:00', '--job-id', '9', '--raw', '--subdir', 'DAGS_FOLDER/en_species_dag.py', '--cfg-path', '/tmp/tmpupczxvgp']
[2024-11-17T19:43:51.015+0000] {standard_task_runner.py:105} INFO - Job 9: Subtask load_data_to_s3
[2024-11-17T19:43:51.035+0000] {task_command.py:467} INFO - Running <TaskInstance: en_species_etl.load_data_to_s3 manual__2024-11-17T19:43:48.866514+00:00 [running]> on host 215aff354163
[2024-11-17T19:43:51.063+0000] {taskinstance.py:3132} INFO - Exporting env vars: AIRFLOW_CTX_DAG_OWNER='***' AIRFLOW_CTX_DAG_ID='en_species_etl' AIRFLOW_CTX_TASK_ID='load_data_to_s3' AIRFLOW_CTX_EXECUTION_DATE='2024-11-17T19:43:48.866514+00:00' AIRFLOW_CTX_TRY_NUMBER='1' AIRFLOW_CTX_DAG_RUN_ID='manual__2024-11-17T19:43:48.866514+00:00'
[2024-11-17T19:43:51.063+0000] {taskinstance.py:731} INFO - ::endgroup::
[2024-11-17T19:43:51.073+0000] {base.py:84} INFO - Retrieving connection 's3_conn'
[2024-11-17T19:43:51.073+0000] {connection_wrapper.py:328} INFO - AWS Connection (conn_id='s3_conn', conn_type='aws') credentials retrieved from extra.
[2024-11-17T19:43:51.892+0000] {taskinstance.py:3311} ERROR - Task failed with exception
Traceback (most recent call last):
  File "/home/airflow/.local/lib/python3.12/site-packages/airflow/models/taskinstance.py", line 767, in _execute_task
    result = _execute_callable(context=context, **execute_callable_kwargs)
             ^^^^^^^^^^^^^^^^^^^^^^^^^^^^^^^^^^^^^^^^^^^^^^^^^^^^^^^^^^^^^
  File "/home/airflow/.local/lib/python3.12/site-packages/airflow/models/taskinstance.py", line 733, in _execute_callable
    return ExecutionCallableRunner(
           ^^^^^^^^^^^^^^^^^^^^^^^^
  File "/home/airflow/.local/lib/python3.12/site-packages/airflow/utils/operator_helpers.py", line 252, in run
    return self.func(*args, **kwargs)
           ^^^^^^^^^^^^^^^^^^^^^^^^^^
  File "/home/airflow/.local/lib/python3.12/site-packages/airflow/models/baseoperator.py", line 417, in wrapper
    return func(self, *args, **kwargs)
           ^^^^^^^^^^^^^^^^^^^^^^^^^^^
  File "/home/airflow/.local/lib/python3.12/site-packages/airflow/operators/python.py", line 238, in execute
    return_value = self.execute_callable()
                   ^^^^^^^^^^^^^^^^^^^^^^^
  File "/home/airflow/.local/lib/python3.12/site-packages/airflow/operators/python.py", line 256, in execute_callable
    return runner.run(*self.op_args, **self.op_kwargs)
           ^^^^^^^^^^^^^^^^^^^^^^^^^^^^^^^^^^^^^^^^^^^
  File "/home/airflow/.local/lib/python3.12/site-packages/airflow/utils/operator_helpers.py", line 252, in run
    return self.func(*args, **kwargs)
           ^^^^^^^^^^^^^^^^^^^^^^^^^^
  File "/opt/airflow/dags/en_species_dag.py", line 64, in load
    hook.load_file(filename='/opt/airflow/processed_data/main.csv', key='main.csv', bucket_name=bucket_name)
  File "/home/airflow/.local/lib/python3.12/site-packages/airflow/providers/amazon/aws/hooks/s3.py", line 155, in wrapper
    return func(*bound_args.args, **bound_args.kwargs)
           ^^^^^^^^^^^^^^^^^^^^^^^^^^^^^^^^^^^^^^^^^^^
  File "/home/airflow/.local/lib/python3.12/site-packages/airflow/providers/amazon/aws/hooks/s3.py", line 129, in wrapper
    return func(*bound_args.args, **bound_args.kwargs)
           ^^^^^^^^^^^^^^^^^^^^^^^^^^^^^^^^^^^^^^^^^^^
  File "/home/airflow/.local/lib/python3.12/site-packages/airflow/providers/amazon/aws/hooks/s3.py", line 1097, in load_file
    raise ValueError(f"The key {key} already exists.")
ValueError: The key main.csv already exists.
[2024-11-17T19:43:51.909+0000] {taskinstance.py:1225} INFO - Marking task as FAILED. dag_id=en_species_etl, task_id=load_data_to_s3, run_id=manual__2024-11-17T19:43:48.866514+00:00, execution_date=20241117T194348, start_date=20241117T194351, end_date=20241117T194351
[2024-11-17T19:43:51.919+0000] {taskinstance.py:340} INFO - ::group::Post task execution logs
[2024-11-17T19:43:51.920+0000] {standard_task_runner.py:124} ERROR - Failed to execute job 9 for task load_data_to_s3 (The key main.csv already exists.; 448)
Traceback (most recent call last):
  File "/home/airflow/.local/lib/python3.12/site-packages/airflow/task/task_runner/standard_task_runner.py", line 117, in _start_by_fork
    ret = args.func(args, dag=self.dag)
          ^^^^^^^^^^^^^^^^^^^^^^^^^^^^^
  File "/home/airflow/.local/lib/python3.12/site-packages/airflow/cli/cli_config.py", line 49, in command
    return func(*args, **kwargs)
           ^^^^^^^^^^^^^^^^^^^^^
  File "/home/airflow/.local/lib/python3.12/site-packages/airflow/utils/cli.py", line 116, in wrapper
    return f(*args, **kwargs)
           ^^^^^^^^^^^^^^^^^^
  File "/home/airflow/.local/lib/python3.12/site-packages/airflow/cli/commands/task_command.py", line 483, in task_run
    task_return_code = _run_task_by_selected_method(args, _dag, ti)
                       ^^^^^^^^^^^^^^^^^^^^^^^^^^^^^^^^^^^^^^^^^^^^
  File "/home/airflow/.local/lib/python3.12/site-packages/airflow/cli/commands/task_command.py", line 256, in _run_task_by_selected_method
    return _run_raw_task(args, ti)
           ^^^^^^^^^^^^^^^^^^^^^^^
  File "/home/airflow/.local/lib/python3.12/site-packages/airflow/cli/commands/task_command.py", line 341, in _run_raw_task
    return ti._run_raw_task(
           ^^^^^^^^^^^^^^^^^
  File "/home/airflow/.local/lib/python3.12/site-packages/airflow/utils/session.py", line 97, in wrapper
    return func(*args, session=session, **kwargs)
           ^^^^^^^^^^^^^^^^^^^^^^^^^^^^^^^^^^^^^^
  File "/home/airflow/.local/lib/python3.12/site-packages/airflow/models/taskinstance.py", line 3005, in _run_raw_task
    return _run_raw_task(
           ^^^^^^^^^^^^^^
  File "/home/airflow/.local/lib/python3.12/site-packages/airflow/models/taskinstance.py", line 273, in _run_raw_task
    TaskInstance._execute_task_with_callbacks(
  File "/home/airflow/.local/lib/python3.12/site-packages/airflow/models/taskinstance.py", line 3159, in _execute_task_with_callbacks
    result = self._execute_task(context, task_orig)
             ^^^^^^^^^^^^^^^^^^^^^^^^^^^^^^^^^^^^^^
  File "/home/airflow/.local/lib/python3.12/site-packages/airflow/models/taskinstance.py", line 3183, in _execute_task
    return _execute_task(self, context, task_orig)
           ^^^^^^^^^^^^^^^^^^^^^^^^^^^^^^^^^^^^^^^
  File "/home/airflow/.local/lib/python3.12/site-packages/airflow/models/taskinstance.py", line 767, in _execute_task
    result = _execute_callable(context=context, **execute_callable_kwargs)
             ^^^^^^^^^^^^^^^^^^^^^^^^^^^^^^^^^^^^^^^^^^^^^^^^^^^^^^^^^^^^^
  File "/home/airflow/.local/lib/python3.12/site-packages/airflow/models/taskinstance.py", line 733, in _execute_callable
    return ExecutionCallableRunner(
           ^^^^^^^^^^^^^^^^^^^^^^^^
  File "/home/airflow/.local/lib/python3.12/site-packages/airflow/utils/operator_helpers.py", line 252, in run
    return self.func(*args, **kwargs)
           ^^^^^^^^^^^^^^^^^^^^^^^^^^
  File "/home/airflow/.local/lib/python3.12/site-packages/airflow/models/baseoperator.py", line 417, in wrapper
    return func(self, *args, **kwargs)
           ^^^^^^^^^^^^^^^^^^^^^^^^^^^
  File "/home/airflow/.local/lib/python3.12/site-packages/airflow/operators/python.py", line 238, in execute
    return_value = self.execute_callable()
                   ^^^^^^^^^^^^^^^^^^^^^^^
  File "/home/airflow/.local/lib/python3.12/site-packages/airflow/operators/python.py", line 256, in execute_callable
    return runner.run(*self.op_args, **self.op_kwargs)
           ^^^^^^^^^^^^^^^^^^^^^^^^^^^^^^^^^^^^^^^^^^^
  File "/home/airflow/.local/lib/python3.12/site-packages/airflow/utils/operator_helpers.py", line 252, in run
    return self.func(*args, **kwargs)
           ^^^^^^^^^^^^^^^^^^^^^^^^^^
  File "/opt/airflow/dags/en_species_dag.py", line 64, in load
    hook.load_file(filename='/opt/airflow/processed_data/main.csv', key='main.csv', bucket_name=bucket_name)
  File "/home/airflow/.local/lib/python3.12/site-packages/airflow/providers/amazon/aws/hooks/s3.py", line 155, in wrapper
    return func(*bound_args.args, **bound_args.kwargs)
           ^^^^^^^^^^^^^^^^^^^^^^^^^^^^^^^^^^^^^^^^^^^
  File "/home/airflow/.local/lib/python3.12/site-packages/airflow/providers/amazon/aws/hooks/s3.py", line 129, in wrapper
    return func(*bound_args.args, **bound_args.kwargs)
           ^^^^^^^^^^^^^^^^^^^^^^^^^^^^^^^^^^^^^^^^^^^
  File "/home/airflow/.local/lib/python3.12/site-packages/airflow/providers/amazon/aws/hooks/s3.py", line 1097, in load_file
    raise ValueError(f"The key {key} already exists.")
ValueError: The key main.csv already exists.
[2024-11-17T19:43:51.945+0000] {local_task_job_runner.py:266} INFO - Task exited with return code 1
[2024-11-17T19:43:51.959+0000] {taskinstance.py:3895} INFO - 0 downstream tasks scheduled from follow-on schedule check
[2024-11-17T19:43:51.960+0000] {local_task_job_runner.py:245} INFO - ::endgroup::
